<?xml version='1.0'?>
<!--
  The file is converted from allegro_hand_description_right.urdf, which is originally converted from the .xacro file. Some modifications on the model is conducted manually, which may need further adjustement - the damping values of the joints are minimized for about 300 times based on the original value. The inertia of several joints have been modified in order to get the model running: the ixy, ixz, iyz components of the joints have been minimized for 1e10 orders. The han is also welded to the world frame, which may need further modification.
-->
<sdf version='1.6'>
  <model name='allegro_hand_left'>
    <link name='hand_root'>
      <pose frame=''>0 0 0 0 -0 0</pose>
      <inertial>
        <pose frame=''>0 0 0 0 -0 0</pose>
        <mass>0.4154</mass>
        <inertia>
            <ixx>0.00078649</ixx>
            <ixy>-3.00638e-06</ixy>
            <ixz>-0.000218183</ixz>
            <iyy>0.000453621</iyy>
            <iyz>5.78419e-05</iyz>
            <izz>0.00178453</izz>
        </inertia>
      </inertial>
      <collision name='hand_root_fixed_joint_lump__palm_link_collision'>
        <pose frame=''>-0.0093 0 0.0475 0 -0 0</pose>
        <geometry>
          <box>
            <size>0.0408 0.113 0.095</size>
          </box>
        </geometry>
      </collision>
      <visual name='hand_root_fixed_joint_lump__palm_link_visual'>
        <pose frame=''>0 0 0.095 -1.5708 0 0</pose>
        <geometry>
          <mesh>
            <scale>1 1 1</scale>
            <uri>../meshes/base_link_left.obj</uri>
          </mesh>
        </geometry>
      </visual>
    </link>

    
    <link name='link_8'>
      <pose frame=''>0 0.0435 0.093458 -0.087267 0 0</pose>
      <inertial>
        <pose frame=''>0 0 0 0 -0 0</pose>
        <mass>0.0119</mass>
        <inertia>
          <ixx>1.53258e-06</ixx>
          <ixy>3.49081e-10</ixy>
          <ixz>2.25302e-08</ixz>
          <iyy>7.54004e-07</iyy>
          <iyz>-3.0083e-09</iyz>
          <izz>1.91655e-06</izz>
        </inertia>
      </inertial>
      <collision name='link_8_collision'>
        <pose frame=''>0 0 0.0082 0 -0 0</pose>
        <geometry>
          <box>
            <size>0.0196 0.0275 0.0164</size>
          </box>
        </geometry>
      </collision>
      <visual name='link_8_visual'>
        <pose frame=''>0 0 0 0 -0 0</pose>
        <geometry>
          <mesh>
            <scale>1 1 1</scale>
            <uri>../meshes/link_0.0.obj</uri>
          </mesh>
        </geometry>
      </visual>
    </link>
    <joint name='joint_8' type='revolute'>
      <child>link_8</child>
      <parent>hand_root</parent>
      <axis>
        <xyz>0 -0.087156 -0.996195</xyz>
        <limit>
          <lower>-0.47</lower>
          <upper>0.47</upper>
          <effort>15</effort>
          <velocity>7</velocity>
        </limit>
        <dynamics>
          <damping>1e-2</damping>
          <friction>10</friction>
          <spring_reference>0</spring_reference>
          <spring_stiffness>0</spring_stiffness>
        </dynamics>
        <use_parent_model_frame>1</use_parent_model_frame>
      </axis>
    </joint>
    <link name='link_9'>
      <pose frame=''>0 0.044929 0.109796 -0.087267 0 0</pose>
      <inertial>
        <pose frame=''>0 0 0 0 -0 0</pose>
        <mass>0.065</mass>
        <inertia>
          <ixx>2.45255e-05</ixx>
          <ixy>0</ixy>
          <ixz>0</ixz>
          <iyy>2.70033e-05</iyy>
          <iyz>-7.32186e-07</iyz>
          <izz>5.27799e-05</izz>
        </inertia>
      </inertial>
      <collision name='link_9_collision'>
        <pose frame=''>0 0 0.027 0 -0 0</pose>
        <geometry>
          <box>
            <size>0.0196 0.0275 0.054</size>
          </box>
        </geometry>
      </collision>
      <visual name='link_9_visual'>
        <pose frame=''>0 0 0 0 -0 0</pose>
        <geometry>
          <mesh>
            <scale>1 1 1</scale>
            <uri>../meshes/link_1.0.obj</uri>
          </mesh>
        </geometry>
      </visual>
    </link>
    <joint name='joint_9' type='revolute'>
      <child>link_9</child>
      <parent>link_8</parent>
      <axis>
        <xyz>0 0.996195 -0.087156</xyz>
        <limit>
          <lower>-0.196</lower>
          <upper>1.61</upper>
          <effort>15</effort>
          <velocity>7</velocity>
        </limit>
        <dynamics>
          <damping>1e-2</damping>
          <friction>5</friction>
          <spring_reference>0</spring_reference>
          <spring_stiffness>0</spring_stiffness>
        </dynamics>
        <use_parent_model_frame>1</use_parent_model_frame>
      </axis>
    </joint>
    <link name='link_10'>
      <pose frame=''>0 0.049636 0.16359 -0.087267 0 0</pose>
      <inertial>
        <pose frame=''>0 0 0 0 -0 0</pose>
        <mass>0.0355</mass>
        <inertia>
          <ixx>7.04173e-06</ixx>
          <ixy>1.15391e-09</ixy>
          <ixz>-1.19433e-07</ixz>
          <iyy>6.4006e-06</iyy>
          <iyz>3.03861e-09</iyz>
          <izz>2.78539e-05</izz>
        </inertia>
      </inertial>
      <collision name='link_10_collision'>
        <pose frame=''>0 0 0.0192 0 -0 0</pose>
        <geometry>
          <box>
            <size>0.0196 0.0275 0.0384</size>
          </box>
        </geometry>
      </collision>
      <visual name='link_10_visual'>
        <pose frame=''>0 0 0 0 -0 0</pose>
        <geometry>
          <mesh>
            <scale>1 1 1</scale>
            <uri>../meshes/link_2.0.obj</uri>
          </mesh>
        </geometry>
      </visual>
    </link>
    <joint name='joint_10' type='revolute'>
      <child>link_10</child>
      <parent>link_9</parent>
      <axis>
        <xyz>0 0.996195 -0.087156</xyz>
        <limit>
          <lower>-0.174</lower>
          <upper>1.709</upper>
          <effort>15</effort>
          <velocity>7</velocity>
        </limit>
        <dynamics>
          <damping>2.5e-2</damping>
          <friction>10</friction>
          <spring_reference>0</spring_reference>
          <spring_stiffness>0</spring_stiffness>
        </dynamics>
        <use_parent_model_frame>1</use_parent_model_frame>
      </axis>
    </joint>
    <link name='link_11'>
      <pose frame=''>0 0.052983 0.201844 -0.087267 0 0</pose>
      <inertial>
        <pose frame=''>0 0 0.016991 0 -0 0</pose>
        <mass>0.0264</mass>
        <inertia>
          <ixx>2.54817e-06</ixx>
          <ixy>1.186e-09</ixy>
          <ixz>-8.28734e-08</ixz>
          <iyy>1.73395e-06</iyy>
          <iyz>1.62532e-08</iyz>
          <izz>1.25656e-05</izz>
        </inertia>
      </inertial>
      <collision name='link_11_collision'>
        <pose frame=''>0 0 0.01335 0 -0 0</pose>
        <geometry>
          <box>
            <size>0.0196 0.0275 0.0267</size>
          </box>
        </geometry>
      </collision>
      <collision name='link_11_tip_collision_1'>
        <pose frame=''>0 0 0.0267 0 -0 0</pose>
        <geometry>
          <sphere>
            <radius>0.012</radius>
          </sphere>
        </geometry>
      </collision>
      <visual name='link_11_visual'>
        <pose frame=''>0 0 0 0 -0 0</pose>
        <geometry>
          <mesh>
            <scale>1 1 1</scale>
            <uri>../meshes/link_3.0.obj</uri>
          </mesh>
        </geometry>
      </visual>
      <visual name='link_11_tip_visual_1'>
        <pose frame=''>0 0 0.0267 0 -0 0</pose>
        <geometry>
          <mesh>
            <scale>1 1 1</scale>
            <uri>../meshes/link_3.0_tip.obj</uri>
          </mesh>
        </geometry>
      </visual>
    </link>
    <joint name='joint_11' type='revolute'>
      <child>link_11</child>
      <parent>link_10</parent>
      <axis>
        <xyz>0 0.996195 -0.087156</xyz>
        <limit>
          <lower>-0.227</lower>
          <upper>1.618</upper>
          <effort>15</effort>
          <velocity>7</velocity>
        </limit>
        <dynamics>
          <damping>3.2e-2</damping>
          <friction>12</friction>
          <spring_reference>0</spring_reference>
          <spring_stiffness>0</spring_stiffness>
        </dynamics>
        <use_parent_model_frame>1</use_parent_model_frame>
      </axis>
    </joint>
    <link name='link_12'>
      <pose frame=''>-0.0182 -0.019333 0.049013 -3.14159 -1.48353 -1.5708</pose>
      <inertial>
        <pose frame=''>0 0 0 0 -0 0</pose>
        <mass>0.0176</mass>
        <inertia>
            <ixx>9.82656e-06</ixx>
            <ixy>2.53566e-06</ixy>
            <ixz>-3.84773e-06</ixz>
            <iyy>6.05161e-06</iyy>
            <iyz>-2.08562e-06</iyz>
            <izz>5.99898e-06</izz>
        </inertia>
      </inertial>
      <collision name='link_12_collision'>
        <pose frame=''>-0.0179 0.009 0.0145 0 -0 0</pose>
        <geometry>
          <box>
            <size>0.0358 0.034 0.0455</size>
          </box>
        </geometry>
      </collision>
      <visual name='link_12_visual'>
        <pose frame=''>0 0 0 3.14159 -0 0</pose>
        <geometry>
          <mesh>
            <scale>1 1 1</scale>
            <uri>../meshes/link_12.0_left.obj</uri>
          </mesh>
        </geometry>
      </visual>
    </link>
    <joint name='joint_12' type='revolute'>
      <child>link_12</child>
      <parent>hand_root</parent>
      <axis>
        <xyz>-0 -0.087156 0.996195</xyz>
        <limit>
          <lower>0.263</lower>
          <upper>1.396</upper>
          <effort>15</effort>
          <velocity>7</velocity>
        </limit>
        <dynamics>
          <damping>1e-2</damping>
          <friction>10</friction>
          <spring_reference>0</spring_reference>
          <spring_stiffness>0</spring_stiffness>
        </dynamics>
        <use_parent_model_frame>1</use_parent_model_frame>
      </axis>
    </joint>
    <link name='link_13'>
      <pose frame=''>-0.0132 -0.056728 0.018638 -3.14159 -1.48353 -1.5708</pose>
      <inertial>
        <pose frame=''>0 0 0 0 -0 0</pose>
        <mass>0.0119</mass>
        <inertia>
          <ixx>1.53027e-06</ixx>
          <ixy>3.49053e-10</ixy>
          <ixz>2.33045e-08</ixz>
          <iyy>7.52734e-07</iyy>
          <iyz>-3.49991e-09</iyz>
          <izz>1.89036e-06</izz>
        </inertia>
      </inertial>
      <!--
      <collision name='link_13_collision'>
        <pose frame=''>0 0 0.00885 0 -0 0</pose>
        <geometry>
          <box>
            <size>0.0196 0.0275 0.0177</size>
          </box>
        </geometry>
      </collision>
    -->
      <visual name='link_13_visual'>
        <pose frame=''>0 0 0 0 -0 0</pose>
        <geometry>
          <mesh>
            <scale>1 1 1</scale>
            <uri>../meshes/link_13.0.obj</uri>
          </mesh>
        </geometry>
      </visual>
    </link>
    <joint name='joint_13' type='revolute'>
      <child>link_13</child>
      <parent>link_12</parent>
      <axis>
        <xyz>0 0.996195 0.087156</xyz>
        <limit>
          <lower>-0.105</lower>
          <upper>1.163</upper>
          <effort>15</effort>
          <velocity>7</velocity>
        </limit>
        <dynamics>
          <damping>1e-2</damping>
          <friction>5</friction>
          <spring_reference>0</spring_reference>
          <spring_stiffness>0</spring_stiffness>
        </dynamics>
        <use_parent_model_frame>1</use_parent_model_frame>
      </axis>
    </joint>
    <link name='link_14'>
      <pose frame=''>-0.0132 -0.074361 0.017096 -3.14159 -1.48353 -1.5708</pose>
      <inertial>
        <pose frame=''>0 0 0 0 -0 0</pose>
        <mass>0.038</mass>
        <inertia>
          <ixx>1.03177e-05</ixx>
          <ixy>1.11158e-09</ixy>
          <ixz>2.59552e-08</ixz>
          <iyy>9.01723e-06</iyy>
          <iyz>-7.49519e-08</iyz>
          <izz>3.00194e-05</izz>
        </inertia>
      </inertial>
      <collision name='link_14_collision'>
        <pose frame=''>0 0 0.0257 0 -0 0</pose>
        <geometry>
          <box>
            <size>0.0196 0.0275 0.0514</size>
          </box>
        </geometry>
      </collision>
      <visual name='link_14_visual'>
        <pose frame=''>0 0 0 0 -0 0</pose>
        <geometry>
          <mesh>
            <scale>1 1 1</scale>
            <uri>../meshes/link_14.0.obj</uri>
          </mesh>
        </geometry>
      </visual>
    </link>
    <joint name='joint_14' type='revolute'>
      <child>link_14</child>
      <parent>link_13</parent>
      <axis>
        <xyz>-1 0 -0</xyz>
        <limit>
          <lower>-0.189</lower>
          <upper>1.644</upper>
          <effort>15</effort>
          <velocity>7</velocity>
        </limit>
        <dynamics>
          <damping>1e-2</damping>
          <friction>10</friction>
          <spring_reference>0</spring_reference>
          <spring_stiffness>0</spring_stiffness>
        </dynamics>
        <use_parent_model_frame>1</use_parent_model_frame>
      </axis>
    </joint>
    <link name='link_15'>
      <pose frame=''>-0.0132 -0.125565 0.012616 -3.14159 -1.48353 -1.5708</pose>
      <inertial>
        <pose frame=''>0 0 0.012781 0 -0 0</pose>
        <mass>0.0556</mass>
        <inertia>
          <ixx>4.08812e-05</ixx>
          <ixy>0</ixy>
          <ixz>0</ixz>
          <iyy>3.59803e-05</iyy>
          <iyz>2.69559e-08</iyz>
          <izz>4.92034e-05</izz>
        </inertia>
      </inertial>
      <collision name='link_15_collision'>
        <pose frame=''>0 0 0.02115 0 -0 0</pose>
        <geometry>
          <box>
            <size>0.0196 0.0275 0.0423</size>
          </box>
        </geometry>
      </collision>
      <collision name='link_15_tip_collision_1'>
        <pose frame=''>0 0 0.0423 0 -0 0</pose>
        <geometry>
          <sphere>
            <radius>0.012</radius>
          </sphere>
        </geometry>
      </collision>
      <visual name='link_15_visual'>
        <pose frame=''>0 0 0 0 -0 0</pose>
        <geometry>
          <mesh>
            <scale>1 1 1</scale>
            <uri>../meshes/link_15.0.obj</uri>
          </mesh>
        </geometry>
      </visual>
      <visual name='link_15_tip_visual_1'>
        <pose frame=''>0 0 0.0423 0 -0 0</pose>
        <geometry>
          <mesh>
            <scale>1 1 1</scale>
            <uri>../meshes/link_15.0_tip.obj</uri>
          </mesh>
        </geometry>
      </visual>
    </link>
    <joint name='joint_15' type='revolute'>
      <child>link_15</child>
      <parent>link_14</parent>
      <axis>
        <xyz>-1 0 -0</xyz>
        <limit>
          <lower>-0.162</lower>
          <upper>1.719</upper>
          <effort>15</effort>
          <velocity>7</velocity>
        </limit>
        <dynamics>
          <damping>1e-2</damping>
          <friction>12</friction>
          <spring_reference>0</spring_reference>
          <spring_stiffness>0</spring_stiffness>
        </dynamics>
        <use_parent_model_frame>1</use_parent_model_frame>
      </axis>
    </joint>
    <link name='link_4'>
      <pose frame=''>0 0 0.0957 0 -0 0</pose>
      <inertial>
        <pose frame=''>0 0 0 0 -0 0</pose>
        <mass>0.0119</mass>
        <inertia>
          <ixx>1.53258e-06</ixx>
          <ixy>3.49081e-10</ixy>
          <ixz>2.25302e-08</ixz>
          <iyy>7.54004e-07</iyy>
          <iyz>-3.0083e-09</iyz>
          <izz>1.91655e-06</izz>
        </inertia>
      </inertial>
      <collision name='link_4_collision'>
        <pose frame=''>0 0 0.0082 0 -0 0</pose>
        <geometry>
          <box>
            <size>0.0196 0.0275 0.0164</size>
          </box>
        </geometry>
      </collision>
      <visual name='link_4_visual'>
        <pose frame=''>0 0 0 0 -0 0</pose>
        <geometry>
          <mesh>
            <scale>1 1 1</scale>
            <uri>../meshes/link_0.0.obj</uri>
          </mesh>
        </geometry>
      </visual>
    </link>
    <joint name='joint_4' type='revolute'>
      <child>link_4</child>
      <parent>hand_root</parent>
      <axis>
        <xyz>0 0 -1</xyz>
        <limit>
          <lower>-0.47</lower>
          <upper>0.47</upper>
          <effort>15</effort>
          <velocity>7</velocity>
        </limit>
        <dynamics>
          <damping>1e-2</damping>
          <friction>10</friction>
          <spring_reference>0</spring_reference>
          <spring_stiffness>0</spring_stiffness>
        </dynamics>
        <use_parent_model_frame>1</use_parent_model_frame>
      </axis>
    </joint>
    <link name='link_5'>
      <pose frame=''>0 0 0.1121 0 -0 0</pose>
      <inertial>
        <pose frame=''>0 0 0 0 -0 0</pose>
        <mass>0.065</mass>
        <inertia>
          <ixx>2.45255e-05</ixx>
          <ixy>0</ixy>
          <ixz>0</ixz>
          <iyy>2.70033e-05</iyy>
          <iyz>-7.32186e-07</iyz>
          <izz>5.27799e-05</izz>
        </inertia>
      </inertial>
      <collision name='link_5_collision'>
        <pose frame=''>0 0 0.027 0 -0 0</pose>
        <geometry>
          <box>
            <size>0.0196 0.0275 0.054</size>
          </box>
        </geometry>
      </collision>
      <visual name='link_5_visual'>
        <pose frame=''>0 0 0 0 -0 0</pose>
        <geometry>
          <mesh>
            <scale>1 1 1</scale>
            <uri>../meshes/link_1.0.obj</uri>
          </mesh>
        </geometry>
      </visual>
    </link>
    <joint name='joint_5' type='revolute'>
      <child>link_5</child>
      <parent>link_4</parent>
      <axis>
        <xyz>0 1 0</xyz>
        <limit>
          <lower>-0.196</lower>
          <upper>1.61</upper>
          <effort>15</effort>
          <velocity>7</velocity>
        </limit>
        <dynamics>
          <damping>1e-2</damping>
          <friction>5</friction>
          <spring_reference>0</spring_reference>
          <spring_stiffness>0</spring_stiffness>
        </dynamics>
        <use_parent_model_frame>1</use_parent_model_frame>
      </axis>
    </joint>
    <link name='link_6'>
      <pose frame=''>0 0 0.1661 0 -0 0</pose>
      <inertial>
        <pose frame=''>0 0 0 0 -0 0</pose>
        <mass>0.0355</mass>
        <inertia>
          <ixx>7.04173e-06</ixx>
          <ixy>1.15391e-09</ixy>
          <ixz>-1.19433e-07</ixz>
          <iyy>6.4006e-06</iyy>
          <iyz>3.03861e-09</iyz>
          <izz>2.78539e-05</izz>
        </inertia>
      </inertial>
      <collision name='link_6_collision'>
        <pose frame=''>0 0 0.0192 0 -0 0</pose>
        <geometry>
          <box>
            <size>0.0196 0.0275 0.0384</size>
          </box>
        </geometry>
      </collision>
      <visual name='link_6_visual'>
        <pose frame=''>0 0 0 0 -0 0</pose>
        <geometry>
          <mesh>
            <scale>1 1 1</scale>
            <uri>../meshes/link_2.0.obj</uri>
          </mesh>
        </geometry>
      </visual>
    </link>
    <joint name='joint_6' type='revolute'>
      <child>link_6</child>
      <parent>link_5</parent>
      <axis>
        <xyz>0 1 0</xyz>
        <limit>
          <lower>-0.174</lower>
          <upper>1.709</upper>
          <effort>15</effort>
          <velocity>7</velocity>
        </limit>
        <dynamics>
          <damping>2.5e-2</damping>
          <friction>10</friction>
          <spring_reference>0</spring_reference>
          <spring_stiffness>0</spring_stiffness>
        </dynamics>
        <use_parent_model_frame>1</use_parent_model_frame>
      </axis>
    </joint>
    <link name='link_7'>
      <pose frame=''>0 0 0.2045 0 -0 0</pose>
      <inertial>
        <pose frame=''>0 0 0.016991 0 -0 0</pose>
        <mass>0.0264</mass>
        <inertia>
          <ixx>2.54817e-06</ixx>
          <ixy>1.186e-09</ixy>
          <ixz>-8.28734e-08</ixz>
          <iyy>1.73395e-06</iyy>
          <iyz>1.62532e-08</iyz>
          <izz>1.25656e-05</izz>
        </inertia>
      </inertial>
      <collision name='link_7_collision'>
        <pose frame=''>0 0 0.01335 0 -0 0</pose>
        <geometry>
          <box>
            <size>0.0196 0.0275 0.0267</size>
          </box>
        </geometry>
      </collision>
      <collision name='link_7_tip_collision_1'>
        <pose frame=''>0 0 0.0267 0 -0 0</pose>
        <geometry>
          <sphere>
            <radius>0.012</radius>
          </sphere>
        </geometry>
      </collision>
      <visual name='link_7_visual'>
        <pose frame=''>0 0 0 0 -0 0</pose>
        <geometry>
          <mesh>
            <scale>1 1 1</scale>
            <uri>../meshes/link_3.0.obj</uri>
          </mesh>
        </geometry>
      </visual>
      <visual name='link_7_tip_visual_1'>
        <pose frame=''>0 0 0.0267 0 -0 0</pose>
        <geometry>
          <mesh>
            <scale>1 1 1</scale>
            <uri>../meshes/link_3.0_tip.obj</uri>
          </mesh>
        </geometry>
      </visual>
    </link>
    <joint name='joint_7' type='revolute'>
      <child>link_7</child>
      <parent>link_6</parent>
      <axis>
        <xyz>0 1 0</xyz>
        <limit>
          <lower>-0.227</lower>
          <upper>1.618</upper>
          <effort>15</effort>
          <velocity>7</velocity>
        </limit>
        <dynamics>
          <damping>3.2e-2</damping>
          <friction>12</friction>
          <spring_reference>0</spring_reference>
          <spring_stiffness>0</spring_stiffness>
        </dynamics>
        <use_parent_model_frame>1</use_parent_model_frame>
      </axis>
    </joint>
    <link name='link_0'>
      <pose frame=''>0 -0.0435 0.093458 0.087267 -0 0</pose>
      <inertial>
        <pose frame=''>0 0 0 0 -0 0</pose>
        <mass>0.0119</mass>
        <inertia>
          <ixx>1.53258e-06</ixx>
          <ixy>3.49081e-10</ixy>
          <ixz>2.25302e-08</ixz>
          <iyy>7.54004e-07</iyy>
          <iyz>-3.0083e-09</iyz>
          <izz>1.91655e-06</izz>
        </inertia>
      </inertial>
      <collision name='link_0_collision'>
        <pose frame=''>0 0 0.0082 0 -0 0</pose>
        <geometry>
          <box>
            <size>0.0196 0.0275 0.0164</size>
          </box>
        </geometry>
      </collision>
      <visual name='link_0_visual'>
        <pose frame=''>0 0 0 0 -0 0</pose>
        <geometry>
          <mesh>
            <scale>1 1 1</scale>
            <uri>../meshes/link_0.0.obj</uri>
          </mesh>
        </geometry>
      </visual>
    </link>
    <joint name='joint_0' type='revolute'>
      <child>link_0</child>
      <parent>hand_root</parent>
      <axis>
        <xyz>0 0.087156 -0.996195</xyz>
        <limit>
          <lower>-0.47</lower>
          <upper>0.47</upper>
          <effort>15</effort>
          <velocity>7</velocity>
        </limit>
        <dynamics>
          <damping>1e-2</damping>
          <friction>10</friction>
          <spring_reference>0</spring_reference>
          <spring_stiffness>0</spring_stiffness>
        </dynamics>
        <use_parent_model_frame>1</use_parent_model_frame>
      </axis>
    </joint>
    <link name='link_1'>
      <pose frame=''>0 -0.044929 0.109796 0.087267 -0 0</pose>
      <inertial>
        <pose frame=''>0 0 0 0 -0 0</pose>
        <mass>0.065</mass>
        <inertia>
          <ixx>2.45255e-05</ixx>
          <ixy>0</ixy>
          <ixz>0</ixz>
          <iyy>2.70033e-05</iyy>
          <iyz>-7.32186e-07</iyz>
          <izz>5.27799e-05</izz>
        </inertia>
      </inertial>
      <collision name='link_1_collision'>
        <pose frame=''>0 0 0.027 0 -0 0</pose>
        <geometry>
          <box>
            <size>0.0196 0.0275 0.054</size>
          </box>
        </geometry>
      </collision>
      <visual name='link_1_visual'>
        <pose frame=''>0 0 0 0 -0 0</pose>
        <geometry>
          <mesh>
            <scale>1 1 1</scale>
            <uri>../meshes/link_1.0.obj</uri>
          </mesh>
        </geometry>
      </visual>
    </link>
    <joint name='joint_1' type='revolute'>
      <child>link_1</child>
      <parent>link_0</parent>
      <axis>
        <xyz>0 0.996195 0.087156</xyz>
        <limit>
          <lower>-0.196</lower>
          <upper>1.61</upper>
          <effort>15</effort>
          <velocity>7</velocity>
        </limit>
        <dynamics>
          <damping>1e-2</damping>
          <friction>5</friction>
          <spring_reference>0</spring_reference>
          <spring_stiffness>0</spring_stiffness>
        </dynamics>
        <use_parent_model_frame>1</use_parent_model_frame>
      </axis>
    </joint>
    <link name='link_2'>
      <pose frame=''>0 -0.049636 0.16359 0.087267 -0 0</pose>
      <inertial>
        <pose frame=''>0 0 0 0 -0 0</pose>
        <mass>0.0355</mass>
        <inertia>
          <ixx>7.04173e-06</ixx>
          <ixy>1.15391e-09</ixy>
          <ixz>-1.19433e-07</ixz>
          <iyy>6.4006e-06</iyy>
          <iyz>3.03861e-09</iyz>
          <izz>2.78539e-05</izz>
        </inertia>
      </inertial>
      <collision name='link_2_collision'>
        <pose frame=''>0 0 0.0192 0 -0 0</pose>
        <geometry>
          <box>
            <size>0.0196 0.0275 0.0384</size>
          </box>
        </geometry>
      </collision>
      <visual name='link_2_visual'>
        <pose frame=''>0 0 0 0 -0 0</pose>
        <geometry>
          <mesh>
            <scale>1 1 1</scale>
            <uri>../meshes/link_2.0.obj</uri>
          </mesh>
        </geometry>
      </visual>
    </link>
    <joint name='joint_2' type='revolute'>
      <child>link_2</child>
      <parent>link_1</parent>
      <axis>
        <xyz>0 0.996195 0.087156</xyz>
        <limit>
          <lower>-0.174</lower>
          <upper>1.709</upper>
          <effort>15</effort>
          <velocity>7</velocity>
        </limit>
        <dynamics>
          <damping>2.5e-2</damping>
          <friction>10</friction>
          <spring_reference>0</spring_reference>
          <spring_stiffness>0</spring_stiffness>
        </dynamics>
        <use_parent_model_frame>1</use_parent_model_frame>
      </axis>
    </joint>
    <link name='link_3'>
      <pose frame=''>0 -0.052983 0.201844 0.087267 -0 0</pose>
      <inertial>
        <pose frame=''>0 0 0 0 -0 0</pose>
        <mass>0.0264</mass>
        <inertia>
          <ixx>2.54817e-06</ixx>
          <ixy>1.186e-09</ixy>
          <ixz>-8.28734e-08</ixz>
          <iyy>1.73395e-06</iyy>
          <iyz>1.62532e-08</iyz>
          <izz>1.25656e-05</izz>
        </inertia>
      </inertial>
      <collision name='link_3_collision'>
        <pose frame=''>0 0 0.01335 0 -0 0</pose>
        <geometry>
          <box>
            <size>0.0196 0.0275 0.0267</size>
          </box>
        </geometry>
      </collision>
      <collision name='link_3_tip_collision_1'>
        <pose frame=''>0 0 0.0267 0 -0 0</pose>
        <geometry>
          <sphere>
            <radius>0.012</radius>
          </sphere>
        </geometry>
      </collision>
      <visual name='link_3_visual'>
        <pose frame=''>0 0 0 0 -0 0</pose>
        <geometry>
          <mesh>
            <scale>1 1 1</scale>
            <uri>../meshes/link_3.0.obj</uri>
          </mesh>
        </geometry>
      </visual>
      <visual name='link_3_tip_visual_1'>
        <pose frame=''>0 0 0.0267 0 -0 0</pose>
        <geometry>
          <mesh>
            <scale>1 1 1</scale>
            <uri>../meshes/link_3.0_tip.obj</uri>
          </mesh>
        </geometry>
      </visual>
    </link>
    <joint name='joint_3' type='revolute'>
      <child>link_3</child>
      <parent>link_2</parent>
      <axis>
        <xyz>0 0.996195 0.087156</xyz>
        <limit>
          <lower>-0.227</lower>
          <upper>1.618</upper>
          <effort>15</effort>
          <velocity>7</velocity>
        </limit>
        <dynamics>
          <damping>3.2e-2</damping>
          <friction>12</friction>
          <spring_reference>0</spring_reference>
          <spring_stiffness>0</spring_stiffness>
        </dynamics>
        <use_parent_model_frame>1</use_parent_model_frame>
      </axis>
    </joint>
  </model>
</sdf>
